<mujocoinclude>
    <body name="root" pos="0 0 0"  euler="0 0 3.1416">
        <geom type="mesh" rgba="0.615686 0.811765 0.929412 1" mesh="torso_1_top_torso_1" />
        <geom pos="0.0160579 0.0593235 0.0498109" quat="0 -2.32051e-08 1 -2.32051e-08" type="mesh" rgba="0.972549 0.529412 0.00392157 1" mesh="head_1_x4_1_pcb_1" />
        <geom pos="0.000148008 0.0434136 0.0633109" quat="2.32051e-08 0 -4.64102e-08 -1" type="mesh" rgba="0.768627 0.886275 0.952941 1" mesh="head_1_x4_1_outer_1" />
        <geom pos="-0.0870555 0.0664737 -0.0301332" quat="0.379928 -0.596368 0.596368 -0.379928" type="mesh" rgba="0.917647 0.917647 0.917647 1" mesh="right_arm_1_x8_1_outer_1" />
        <geom pos="-0.0766223 0.032495 -0.00775921" quat="0.596368 0.379928 -0.379928 -0.596368" type="mesh" rgba="0.768627 0.886275 0.952941 1" mesh="right_arm_1_x8_1_pcb_1" />
        <geom pos="0.0870988 0.0664737 -0.0302898" quat="0.379928 -0.596368 -0.596368 0.379928" type="mesh" rgba="0.917647 0.917647 0.917647 1" mesh="left_arm_2_x8_1_outer_1" />
        <geom pos="0.0766657 0.032495 -0.00791584" quat="0.596368 0.379928 0.379928 0.596368" type="mesh" rgba="0.768627 0.886275 0.952941 1" mesh="left_arm_2_x8_1_pcb_1" />
        <geom pos="-0.0521972 0.0576546 -0.0517891" quat="-2.32051e-08 1 0 0" type="mesh" rgba="0.615686 0.811765 0.929412 1" mesh="torso_1_bottom_torso_1" />
        <geom pos="0.101188 0.070595 -0.0581391" quat="0.707107 0.707107 0 0" type="mesh" rgba="0.647059 0.647059 0.647059 1" mesh="torso_1_bottom_back_1" />
        <geom pos="0.0339639 0.0573548 -0.267689" quat="-1 -4.64102e-08 0 0" type="mesh" rgba="0.917647 0.917647 0.917647 1" mesh="torso_1_x8_1_outer_1" />
        <geom pos="-1.4862e-05 0.0326678 -0.267689" quat="6.96153e-08 -1 0 0" type="mesh" rgba="0.768627 0.886275 0.952941 1" mesh="torso_1_x8_1_pcb_1" />
        <geom pos="5.1468e-05 -0.0190049 -0.184989" quat="0 -2.32051e-08 -1 -2.32051e-08" type="mesh" rgba="0.615686 0.811765 0.929412 1" mesh="torso_1_mock_agx_orin_1" />
        <geom pos="0.0419851 0.0326678 -0.252689" quat="-2.32051e-08 1 0 0" type="mesh" rgba="0.615686 0.811765 0.929412 1" mesh="torso_1_breadboard_1" />
        <geom pos="0.0419851 0.0326678 -0.243689" quat="0 -2.32051e-08 -1 -2.32051e-08" type="mesh" rgba="0.615686 0.811765 0.929412 1" mesh="torso_1_accelerometer_1" />
        <geom pos="0.0457081 0.070595 0.0448109" quat="0.707107 0.707107 0 0" type="mesh" rgba="0.647059 0.647059 0.647059 1" mesh="torso_1_top_back_1" />
        <geom pos="-1.4862e-05 0.095595 0.00363456" quat="0.707107 0.707107 0 0" type="mesh" rgba="0.615686 0.811765 0.929412 1" mesh="torso_1_battery_mount_1" />
        <geom pos="-1.4862e-05 0.101945 -0.0860179" quat="0.707107 0.707107 0 0" type="mesh" rgba="0.654902 0.584314 0.823529 1" mesh="torso_1_battery_1" />
        <body name="link_head_1_x4_1_inner_1" pos="0.000148008 0.0434136 0.0633109" quat="0 2.32051e-08 -1 6.96153e-08">
          <joint name="joint_head_1_x4_1_dof_x4" pos="0 0 0" axis="0 0 1" range="-2.51327 0.628319" limited="true"/>
          <geom type="mesh" rgba="0.972549 0.529412 0.00392157 1" mesh="head_1_x4_1_inner_1" />
          <geom pos="0.0105058 0.00467747 -0.0345" quat="-2.32051e-08 1 0 0" type="mesh" rgba="0.980392 0.713726 0.00392157 1" mesh="head_1_neck_1" />
          <geom pos="-0.0153423 -0.0481844 -0.10559" quat="0.672498 0.672499 -0.218508 -0.218508" type="mesh" rgba="0.972549 0.529412 0.00392157 1" mesh="head_1_x4_2_pcb_1" />
          <geom pos="-0.0202786 -0.0279111 -0.1215" quat="-0.672499 0.672498 -0.218508 0.218508" type="mesh" rgba="0.768627 0.886275 0.952941 1" mesh="head_1_x4_2_outer_1" />
          <body name="link_head_1_x4_2_inner_1" pos="-0.0202786 -0.0279111 -0.1215" quat="-0.672498 -0.672499 0.218508 0.218508">
            <joint name="joint_head_1_x4_2_dof_x4" pos="0 0 0" axis="0 0 1" range="-1.5708 0.261799" limited="true"/>
            <geom type="mesh" rgba="0.972549 0.529412 0.00392157 1" mesh="head_1_x4_2_inner_1" />
            <geom pos="-0.0093037 0.00675953 -0.0345" quat="-2.32051e-08 1 0 0" type="mesh" rgba="0.615686 0.811765 0.929412 1" mesh="head_1_head_1" />
            <geom pos="0.0977128 -0.027002 -0.0818784" quat="-0.706138 0.0370071 0.706138 0.0370071" type="mesh" rgba="0.615686 0.811765 0.929412 1" mesh="head_1_eye_1" />
            <geom pos="0.05159 -0.0353264 -0.0818784" quat="-0.0370071 0.706138 -0.0370071 -0.706138" type="mesh" rgba="0.647059 0.647059 0.647059 1" mesh="head_1_ardu_cam_mount_1" />
            <geom pos="0.0799288 -0.0146755 -0.0892784" quat="-0.0370071 0.706138 -0.0370071 -0.706138" type="mesh" rgba="0.615686 0.811765 0.929412 1" mesh="head_1_arducam_no_case_1" />
            <geom pos="0.0831924 -0.0314586 -0.0612784" quat="0.706138 -0.0370071 -0.706138 -0.0370071" type="mesh" rgba="0.615686 0.811765 0.929412 1" mesh="head_1_lcd_2" />
            <geom pos="0.0977128 -0.027002 0.0128784" quat="-0.706138 0.0370071 0.706138 0.0370071" type="mesh" rgba="0.615686 0.811765 0.929412 1" mesh="head_1_eye_2" />
            <geom pos="0.05159 -0.0353264 0.0128784" quat="-0.706138 0.0370071 0.706138 0.0370071" type="mesh" rgba="0.647059 0.647059 0.647059 1" mesh="head_1_ardu_cam_mount_2" />
            <geom pos="0.0799288 -0.0146755 0.0202784" quat="-0.706138 0.0370071 0.706138 0.0370071" type="mesh" rgba="0.615686 0.811765 0.929412 1" mesh="head_1_arducam_no_case_2" />
            <geom pos="0.0831924 -0.0314586 -0.00772164" quat="-0.706138 0.0370071 0.706138 0.0370071" type="mesh" rgba="0.615686 0.811765 0.929412 1" mesh="head_1_lcd_1" />
            <geom pos="-0.059234 0.0177891 -0.116459" quat="0.0370071 0.706138 -0.0370071 0.706138" type="mesh" rgba="0.647059 0.647059 0.647059 1" mesh="head_1_backplate_1" />
            <geom pos="-0.0648867 -0.0168591 -0.01775" quat="0.0370071 0.706138 -0.0370071 0.706138" type="mesh" rgba="0.615686 0.811765 0.929412 1" mesh="head_1_arducam_case_1" />
            <geom pos="-0.0639982 -0.00840571 0.0208608" quat="0.0370071 0.706138 -0.0370071 0.706138" type="mesh" rgba="0.505882 0.533333 0.54902 1" mesh="head_1_xpt2046_touch_1" />
          </body>
        </body>
        <body name="link_right_arm_1_x8_1_inner_1" pos="-0.0766223 0.032495 -0.00775921" quat="0.379928 -0.596368 0.596368 -0.379928">
          <joint name="joint_right_arm_1_x8_1_dof_x8" pos="0 0 0" axis="0 0 1" range="-2.0944 2.0944" limited="true"/>
          <geom type="mesh" rgba="0.972549 0.529412 0.00392157 1" mesh="right_arm_1_x8_1_inner_1" />
          <geom pos="0 0.0155 -0.033" quat="-2.32051e-08 1 0 0" type="mesh" rgba="0.917647 0.917647 0.917647 1" mesh="right_arm_1_shoulder_inner_1" />
          <geom pos="-0.0339787 -0.033 -0.085313" quat="0.707107 0.707107 0 0" type="mesh" rgba="0.917647 0.917647 0.917647 1" mesh="right_arm_1_x8_2_outer_1" />
          <geom pos="0 -0.033 -0.11" quat="-0.707107 0.707107 0 0" type="mesh" rgba="0.768627 0.886275 0.952941 1" mesh="right_arm_1_x8_2_pcb_1" />
          <body name="link_right_arm_1_x8_2_inner_1" pos="0 -0.033 -0.11" quat="0.707107 0.707107 0 0">
            <joint name="joint_right_arm_1_x8_2_dof_x8" pos="0 0 0" axis="0 0 1" range="0 1.91986" limited="true"/>
            <geom type="mesh" rgba="0.972549 0.529412 0.00392157 1" mesh="right_arm_1_x8_2_inner_1" />
            <geom pos="0 0.0155 -0.033" type="mesh" rgba="0.917647 0.917647 0.917647 1" mesh="right_arm_1_shoulder_nontorso_1" />
            <geom pos="-0.036 0.0325 -0.0945" quat="0.5 -0.5 -0.5 -0.5" type="mesh" rgba="0.972549 0.529412 0.00392157 1" mesh="right_arm_1_x6_1_outer_1" />
            <geom pos="0 0.0325 -0.0945" quat="0.5 0.5 -0.5 0.5" type="mesh" rgba="0.980392 0.713726 0.00392157 1" mesh="right_arm_1_x6_1_pcb_1" />
            <body name="link_right_arm_1_x6_1_inner_1" pos="0 0.0325 -0.0945" quat="0.5 -0.5 -0.5 -0.5">
              <joint name="joint_right_arm_1_x6_1_dof_x6" pos="0 0 0" axis="0 0 1" range="-1.0472 3.66519" limited="true"/>
              <geom type="mesh" rgba="0.498039 0.498039 0.498039 1" mesh="right_arm_1_x6_1_inner_1" />
              <geom pos="0.00575 0.00995929 -0.0325" quat="0.5 0 0 -0.866025" type="mesh" rgba="0.972549 0.529412 0.00392157 1" mesh="right_arm_1_elbow_1" />
              <geom pos="-0.000661543 -0.0371458 -0.182823" quat="-0.612372 -0.353553 0.612372 -0.353553" type="mesh" rgba="0.972549 0.529412 0.00392157 1" mesh="right_arm_1_x6_2_outer_1" />
              <geom pos="-0.01625 -0.0281458 -0.214" quat="0.353553 -0.612372 -0.353553 -0.612372" type="mesh" rgba="0.980392 0.713726 0.00392157 1" mesh="right_arm_1_x6_2_pcb_1" />
              <body name="link_right_arm_1_x6_2_inner_1" pos="-0.01625 -0.0281458 -0.214" quat="-0.612372 -0.353553 0.612372 -0.353553">
                <joint name="joint_right_arm_1_x6_2_dof_x6" pos="0 0 0" axis="0 0 1" range="-1.5708 1.5708" limited="true"/>
                <geom type="mesh" rgba="0.498039 0.498039 0.498039 1" mesh="right_arm_1_x6_2_inner_1" />
                <geom pos="0.0115 0 -0.0325" quat="-2.32051e-08 1 0 0" type="mesh" rgba="0.972549 0.529412 0.00392157 1" mesh="right_arm_1_forearm_1" />
                <geom pos="-0.0645 -0.0159099 -0.0534099" quat="-0.5 0.5 -0.5 0.5" type="mesh" rgba="0.972549 0.529412 0.00392157 1" mesh="right_arm_1_x4_1_pcb_1" />
                <geom pos="-0.078 2.87032e-09 -0.0375" quat="-0.5 -0.5 0.5 0.5" type="mesh" rgba="0.768627 0.886275 0.952941 1" mesh="right_arm_1_x4_1_outer_1" />
                <body name="link_right_arm_1_x4_1_inner_1" pos="-0.078 2.87032e-09 -0.0375" quat="0.5 -0.5 0.5 -0.5">
                  <joint name="joint_right_arm_1_x4_1_dof_x4" pos="0 0 0" axis="0 0 1" range="-3.14159 3.14159" limited="true"/>
                  <geom type="mesh" rgba="0.972549 0.529412 0.00392157 1" mesh="right_arm_1_x4_1_inner_1" />
                  <geom pos="-0.0093037 0.00675953 -0.0345" quat="0.99863 0 0 -0.052336" type="mesh" rgba="0.615686 0.811765 0.929412 1" mesh="right_arm_1_hand_1_wrist_1" />
                  <geom pos="-0.0187495 -0.0261836 -0.0660901" quat="0.706138 0.706138 -0.0370071 -0.0370071" type="mesh" rgba="0.972549 0.529412 0.00392157 1" mesh="right_arm_1_hand_1_x4_1_pcb_1" />
                  <geom pos="-0.00151566 -0.0144206 -0.082" quat="-0.706138 0.706138 -0.0370071 0.0370071" type="mesh" rgba="0.768627 0.886275 0.952941 1" mesh="right_arm_1_hand_1_x4_1_outer_1" />
                  <body name="link_right_arm_1_hand_1_x4_1_inner_1" pos="-0.00151566 -0.0144206 -0.082" quat="-0.706138 -0.706138 0.0370071 0.0370071">
                    <joint name="joint_right_arm_1_hand_1_x4_1_dof_x4" pos="0 0 0" axis="0 0 1" range="-2.61799 0.523599" limited="true"/>
                    <geom type="mesh" rgba="0.972549 0.529412 0.00392157 1" mesh="right_arm_1_hand_1_x4_1_inner_1" />
                    <geom pos="-0.0093037 0.00675953 -0.0345" quat="-2.32051e-08 1 0 0" type="mesh" rgba="0.615686 0.811765 0.929412 1" mesh="right_arm_1_hand_1_mount_1" />
                    <geom pos="0.0440795 -0.0839405 -4.20941e-09" quat="-0.32102 0.32102 -0.630037 0.630037" type="mesh" rgba="0.615686 0.811765 0.929412 1" mesh="right_arm_1_hand_1_base_1" />
                    <geom pos="0.0490192 -0.112869 -0.014" quat="-0.32102 -0.32102 0.630037 0.630037" type="mesh" rgba="0.231373 0.380392 0.705882 1" mesh="right_arm_1_hand_1_slide_rail_1" />
                    <geom pos="0.0922279 -0.0670075 0.0212308" quat="-0.32102 -0.32102 0.630037 0.630037" type="mesh" rgba="0.647059 0.647059 0.647059 1" mesh="right_arm_1_hand_1_camera_mount_1" />
                    <geom pos="0.119872 -0.0663878 0.000249996" quat="-0.630037 0.630037 0.32102 -0.32102" type="mesh" rgba="0.615686 0.811765 0.929412 1" mesh="right_arm_1_hand_1_arducam_case_1" />
                    <geom pos="0.0473754 -0.0147545 0.0019099" quat="0.32102 0.32102 -0.630037 -0.630037" type="mesh" rgba="0.972549 0.529412 0.00392157 1" mesh="right_arm_1_hand_1_x4_2_pcb_1" />
                    <geom pos="0.0489455 -0.035561 -0.014" quat="-0.32102 0.32102 -0.630037 0.630037" type="mesh" rgba="0.768627 0.886275 0.952941 1" mesh="right_arm_1_hand_1_x4_2_outer_1" />
                    <body name="link_right_arm_1_hand_1_slide_1" pos="0.139251 -0.00228616 -0.014" quat="-0.218508 -0.218508 -0.672498 -0.672499">
                      <joint name="joint_right_arm_1_hand_1_slider_1" pos="0 0 0" axis="0 0 1" type="slide" range="-0.034 0" limited="true"/>
                      <geom type="mesh" rgba="0.917647 0.917647 0.917647 1" mesh="right_arm_1_hand_1_slide_1" />
                      <geom pos="-0.00499 0.01 -0.033" quat="-1.64085e-08 -0.707107 1.64085e-08 -0.707107" type="mesh" rgba="0.647059 0.647059 0.647059 1" mesh="right_arm_1_hand_1_rack_2" />
                      <geom pos="-0.04949 0.01 -0.033" quat="-1.64085e-08 -0.707107 1.64085e-08 -0.707107" type="mesh" rgba="0.647059 0.647059 0.647059 1" mesh="right_arm_1_hand_1_gripper_1" />
                    </body>
                    <body name="link_right_arm_1_hand_1_slide_2" pos="0.0452051 -0.131729 -0.014" quat="0.218508 -0.218508 -0.672499 0.672498">
                      <joint name="joint_right_arm_1_hand_1_slider_2" pos="0 0 0" axis="0 0 1" type="slide" range="-0.034 0" limited="true"/>
                      <geom type="mesh" rgba="0.917647 0.917647 0.917647 1" mesh="right_arm_1_hand_1_slide_2" />
                      <geom pos="-0.00499 -0.01 -0.033" quat="-1.64085e-08 -0.707107 1.64085e-08 -0.707107" type="mesh" rgba="0.647059 0.647059 0.647059 1" mesh="right_arm_1_hand_1_rack_1" />
                      <geom pos="-0.04949 0.01 -0.033" quat="-1.64085e-08 -0.707107 1.64085e-08 -0.707107" type="mesh" rgba="0.647059 0.647059 0.647059 1" mesh="right_arm_1_hand_1_gripper_2" />
                    </body>
                    <body name="link_right_arm_1_hand_1_x4_2_inner_1" pos="0.0489455 -0.035561 -0.014" quat="-0.32102 -0.32102 0.630037 0.630037">
                      <joint name="joint_right_arm_1_hand_1_x4_2_dof_x4" pos="0 0 0" axis="0 0 1" range="-3.14159 3.14159" limited="true"/>
                      <geom type="mesh" rgba="0.972549 0.529412 0.00392157 1" mesh="right_arm_1_hand_1_x4_2_inner_1" />
                      <geom pos="0.0105058 0.00467747 -0.0345" quat="0.544639 0 0 0.838671" type="mesh" rgba="0.615686 0.811765 0.929412 1" mesh="right_arm_1_hand_1_spur_gear_(26_teeth)_1" />
                      <body name="eer_site" pos="0.0 0.0 -0.14">
                        <site name="eer_site_pos" pos="0 0 0" size="0.01" type="sphere" rgba="0 0.8 0.8 0.3"/>
                        <site name="eer_site_capsule_a" pos="0 0 0" euler="0 0 1.5708" size="0.005 0.03" type="capsule" rgba="0 0.8 0.8 0.3"/>
                        <site name="eer_site_capsule_b" pos="0 0 0" euler="0 1.5708 0" size="0.005 0.02" type="capsule" rgba="0 0.8 0.8 0.3"/>
                      </body>
                      <camera name="grip_r" pos="0 0.05 0" fovy="20" mode="targetbody" target="eer_site" />
                    </body>
                  </body>
                </body>
              </body>
            </body>
          </body>
        </body>
        <body name="link_left_arm_2_x8_1_inner_1" pos="0.0766657 0.032495 -0.00791584" quat="0.379928 -0.596368 -0.596368 0.379928">
          <joint name="joint_left_arm_2_x8_1_dof_x8" pos="0 0 0" axis="0 0 1" range="-1.5708 1.5708" limited="true"/>
          <geom type="mesh" rgba="0.972549 0.529412 0.00392157 1" mesh="left_arm_2_x8_1_inner_1" />
          <geom pos="0 0.0155 -0.033" quat="-2.32051e-08 1 0 0" type="mesh" rgba="0.917647 0.917647 0.917647 1" mesh="left_arm_2_shoulder_inner_1" />
          <geom pos="-0.0339787 -0.033 -0.085313" quat="0.707107 0.707107 0 0" type="mesh" rgba="0.917647 0.917647 0.917647 1" mesh="left_arm_2_x8_2_outer_1" />
          <geom pos="0 -0.033 -0.11" quat="-0.707107 0.707107 0 0" type="mesh" rgba="0.768627 0.886275 0.952941 1" mesh="left_arm_2_x8_2_pcb_1" />
          <body name="link_left_arm_2_x8_2_inner_1" pos="0 -0.033 -0.11" quat="0.707107 0.707107 0 0">
            <joint name="joint_left_arm_2_x8_2_dof_x8" pos="0 0 0" axis="0 0 1" range="-1.91986 0" limited="true"/>
            <geom type="mesh" rgba="0.972549 0.529412 0.00392157 1" mesh="left_arm_2_x8_2_inner_1" />
            <geom pos="0 0.0155 -0.033" type="mesh" rgba="0.917647 0.917647 0.917647 1" mesh="left_arm_2_shoulder_nontorso_1" />
            <geom pos="-0.036 0.0325 -0.0945" quat="0.5 -0.5 -0.5 -0.5" type="mesh" rgba="0.972549 0.529412 0.00392157 1" mesh="left_arm_2_x6_1_outer_1" />
            <geom pos="0 0.0325 -0.0945" quat="0.5 0.5 -0.5 0.5" type="mesh" rgba="0.980392 0.713726 0.00392157 1" mesh="left_arm_2_x6_1_pcb_1" />
            <body name="link_left_arm_2_x6_1_inner_1" pos="0 0.0325 -0.0945" quat="0.5 -0.5 -0.5 -0.5">
              <joint name="joint_left_arm_2_x6_1_dof_x6" pos="0 0 0" axis="0 0 1" range="-3.66519 1.0472" limited="true"/>
              <geom type="mesh" rgba="0.498039 0.498039 0.498039 1" mesh="left_arm_2_x6_1_inner_1" />
              <geom pos="0.00575 -0.00995929 -0.0325" quat="0.5 0 0 0.866025" type="mesh" rgba="0.972549 0.529412 0.00392157 1" mesh="left_arm_2_elbow_1" />
              <geom pos="-0.0318385 0.0191458 -0.182823" quat="0.612372 -0.353553 -0.612372 -0.353553" type="mesh" rgba="0.972549 0.529412 0.00392157 1" mesh="left_arm_2_x6_2_outer_1" />
              <geom pos="-0.01625 0.0281458 -0.214" quat="0.353553 0.612372 -0.353553 0.612372" type="mesh" rgba="0.980392 0.713726 0.00392157 1" mesh="left_arm_2_x6_2_pcb_1" />
              <body name="link_left_arm_2_x6_2_inner_1" pos="-0.01625 0.0281458 -0.214" quat="0.612372 -0.353553 -0.612372 -0.353553">
                <joint name="joint_left_arm_2_x6_2_dof_x6" pos="0 0 0" axis="0 0 1" range="-1.5708 1.5708" limited="true"/>
                <geom type="mesh" rgba="0.498039 0.498039 0.498039 1" mesh="left_arm_2_x6_2_inner_1" />
                <geom pos="0.0115 0 -0.0325" quat="-2.32051e-08 1 0 0" type="mesh" rgba="0.972549 0.529412 0.00392157 1" mesh="left_arm_2_forearm_1" />
                <geom pos="-0.0645 -0.0159099 -0.0534099" quat="-0.5 0.5 -0.5 0.5" type="mesh" rgba="0.972549 0.529412 0.00392157 1" mesh="left_arm_2_x4_1_pcb_1" />
                <geom pos="-0.078 2.87032e-09 -0.0375" quat="-0.5 -0.5 0.5 0.5" type="mesh" rgba="0.768627 0.886275 0.952941 1" mesh="left_arm_2_x4_1_outer_1" />
                <body name="link_left_arm_2_x4_1_inner_1" pos="-0.078 2.87032e-09 -0.0375" quat="0.5 -0.5 0.5 -0.5">
                  <joint name="joint_left_arm_2_x4_1_dof_x4" pos="0 0 0" axis="0 0 1" range="-3.14159 3.14159" limited="true"/>
                  <geom type="mesh" rgba="0.972549 0.529412 0.00392157 1" mesh="left_arm_2_x4_1_inner_1" />
                  <geom pos="-0.0093037 0.00675953 -0.0345" quat="0.99863 0 0 -0.052336" type="mesh" rgba="0.615686 0.811765 0.929412 1" mesh="left_arm_2_hand_1_wrist_1" />
                  <geom pos="-0.0187495 -0.0261836 -0.0660901" quat="0.706138 0.706138 -0.0370071 -0.0370071" type="mesh" rgba="0.972549 0.529412 0.00392157 1" mesh="left_arm_2_hand_1_x4_1_pcb_1" />
                  <geom pos="-0.00151566 -0.0144206 -0.082" quat="-0.706138 0.706138 -0.0370071 0.0370071" type="mesh" rgba="0.768627 0.886275 0.952941 1" mesh="left_arm_2_hand_1_x4_1_outer_1" />
                  <body name="link_left_arm_2_hand_1_x4_1_inner_1" pos="-0.00151566 -0.0144206 -0.082" quat="-0.706138 -0.706138 0.0370071 0.0370071">
                    <joint name="joint_left_arm_2_hand_1_x4_1_dof_x4" pos="0 0 0" axis="0 0 1" range="-2.61799 0.523599" limited="true"/>
                    <geom type="mesh" rgba="0.972549 0.529412 0.00392157 1" mesh="left_arm_2_hand_1_x4_1_inner_1" />
                    <geom pos="-0.0093037 0.00675953 -0.0345" quat="-2.32051e-08 1 0 0" type="mesh" rgba="0.615686 0.811765 0.929412 1" mesh="left_arm_2_hand_1_mount_1" />
                    <geom pos="0.0440795 -0.0839405 -4.20941e-09" quat="-0.32102 0.32102 -0.630037 0.630037" type="mesh" rgba="0.615686 0.811765 0.929412 1" mesh="left_arm_2_hand_1_base_1" />
                    <geom pos="0.0490192 -0.112869 -0.014" quat="-0.32102 -0.32102 0.630037 0.630037" type="mesh" rgba="0.231373 0.380392 0.705882 1" mesh="left_arm_2_hand_1_slide_rail_1" />
                    <geom pos="0.0922279 -0.0670075 0.0212308" quat="-0.32102 -0.32102 0.630037 0.630037" type="mesh" rgba="0.647059 0.647059 0.647059 1" mesh="left_arm_2_hand_1_camera_mount_1" />
                    <geom pos="0.119872 -0.0663878 0.000249996" quat="-0.630037 0.630037 0.32102 -0.32102" type="mesh" rgba="0.615686 0.811765 0.929412 1" mesh="left_arm_2_hand_1_arducam_case_1" />
                    <geom pos="0.0473754 -0.0147545 0.0019099" quat="0.32102 0.32102 -0.630037 -0.630037" type="mesh" rgba="0.972549 0.529412 0.00392157 1" mesh="left_arm_2_hand_1_x4_2_pcb_1" />
                    <geom pos="0.0489455 -0.035561 -0.014" quat="-0.32102 0.32102 -0.630037 0.630037" type="mesh" rgba="0.768627 0.886275 0.952941 1" mesh="left_arm_2_hand_1_x4_2_outer_1" />
                    <body name="link_left_arm_2_hand_1_slide_1" pos="0.139251 -0.00228616 -0.014" quat="-0.218508 -0.218508 -0.672498 -0.672499">
                      <joint name="joint_left_arm_2_hand_1_slider_1" pos="0 0 0" axis="0 0 1" type="slide" range="-0.034 0" limited="true"/>
                      <geom type="mesh" rgba="0.917647 0.917647 0.917647 1" mesh="left_arm_2_hand_1_slide_1" />
                      <geom pos="-0.00499 0.01 -0.033" quat="-1.64085e-08 -0.707107 1.64085e-08 -0.707107" type="mesh" rgba="0.647059 0.647059 0.647059 1" mesh="left_arm_2_hand_1_rack_2" />
                      <geom pos="-0.04949 0.01 -0.033" quat="-1.64085e-08 -0.707107 1.64085e-08 -0.707107" type="mesh" rgba="0.647059 0.647059 0.647059 1" mesh="left_arm_2_hand_1_gripper_1" />
                    </body>
                    <body name="link_left_arm_2_hand_1_slide_2" pos="0.0452051 -0.131729 -0.014" quat="0.218508 -0.218508 -0.672499 0.672498">
                      <joint name="joint_left_arm_2_hand_1_slider_2" pos="0 0 0" axis="0 0 1" type="slide" range="-0.034 0" limited="true"/>
                      <geom type="mesh" rgba="0.917647 0.917647 0.917647 1" mesh="left_arm_2_hand_1_slide_2" />
                      <geom pos="-0.00499 -0.01 -0.033" quat="-1.64085e-08 -0.707107 1.64085e-08 -0.707107" type="mesh" rgba="0.647059 0.647059 0.647059 1" mesh="left_arm_2_hand_1_rack_1" />
                      <geom pos="-0.04949 0.01 -0.033" quat="-1.64085e-08 -0.707107 1.64085e-08 -0.707107" type="mesh" rgba="0.647059 0.647059 0.647059 1" mesh="left_arm_2_hand_1_gripper_2" />
                    </body>
                    <body name="link_left_arm_2_hand_1_x4_2_inner_1" pos="0.0489455 -0.035561 -0.014" quat="-0.32102 -0.32102 0.630037 0.630037">
                      <joint name="joint_left_arm_2_hand_1_x4_2_dof_x4" pos="0 0 0" axis="0 0 1" range="-3.14159 3.14159" limited="true"/>
                      <geom type="mesh" rgba="0.972549 0.529412 0.00392157 1" mesh="left_arm_2_hand_1_x4_2_inner_1" />
                      <geom pos="0.0105058 0.00467747 -0.0345" quat="0.544639 0 0 0.838671" type="mesh" rgba="0.615686 0.811765 0.929412 1" mesh="left_arm_2_hand_1_spur_gear_(26_teeth)_1" />
                      <body name="eel_site" pos="0.0 0.0 -0.14">
                        <site name="eel_site_pos" pos="0 0 0" size="0.01" type="sphere" rgba="0.8 0.8 0 0.3"/>
                        <site name="eel_site_capsule_a" pos="0 0 0" euler="0 0 1.5708" size="0.005 0.03" type="capsule" rgba="0.8 0.8 0 0.3"/>
                        <site name="eel_site_capsule_b" pos="0 0 0" euler="0 1.5708 0" size="0.005 0.02" type="capsule" rgba="0.8 0.8 0 0.3"/>
                      </body>
                      <camera name="grip_l" pos="0 0.05 0" fovy="20" mode="targetbody" target="eel_site" />
                    </body>
                  </body>
                </body>
              </body>
            </body>
          </body>
        </body>
    </body>
</mujocoinclude>